<?xml version="1.0" ?>

<robot name="wsr" xmlns:xacro="http://www.ros.org/wiki/xacro">

    <material name="Transparency">
        <color rgba="0.0 0.0 0.0 0.1"/>
    </material>
    <material name="Solid">
        <color rgba="0.0 0.0 0.0 1.0"/>
    </material>

    <link name="base_link">
        <visual>
            <origin xyz="0.0 0.01 0.0" rpy="0.0 0.0 0.0"/>
            <geometry>
                <mesh filename="package://wsr_desc/meshes/1-Bottom.stl" scale="0.001 0.001 0.001"/>
            </geometry>
            <material name="">
                <color rgba="1.0 0.0 0.0 1.0"/>
            </material>
        </visual>
        <collision>
            <origin xyz="0.0 0.0 0.0" rpy="0.0 0.0 0.0"/>
            <geometry>
                <cylinder radius="0.0001" length="0.0001"/>
            </geometry>
        </collision>
    </link>

    <link name="Link1">
        <visual>
            <origin xyz="0.0 0.0 0.008" rpy="1.57 0.0 0.15"/>
            <geometry>
                <mesh filename="package://wsr_desc/meshes/Link1.stl" scale="0.01 0.01 0.01"/>
            </geometry>
            <material name="">
                <color rgba="0.0 0.275 0.0 1.0"/>
                
            </material>
        </visual>
    </link>

    <joint name="Joint1" type="revolute">
        <axis xyz="0.0 0.0 1.0"/>
        <limit lower="-0.7854" upper="0.7854" effort="0" velocity="0"/>
        <parent link="base_link"/>
        <child link="Link1"/>
        <origin xyz="0.0 0.0 0.01" rpy="0.0 0.0 0.0"/>
    </joint>

    <link name="Link2">
        <visual>
            <origin xyz="0.004 0.0 0.0" rpy="-1.5707 0.0 0.0"/>
            <geometry>
                <mesh filename="package://wsr_desc/meshes/Link2.stl" scale="0.01 0.01 0.01"/>
            </geometry>
            <material name="">
                <color rgba="0.0 0.0 1.0 1.0"/>
            </material>
        </visual>
    </link>

    <joint name="Joint2" type="revolute">
        <origin xyz="-0.023 -0.042 0.055" rpy="0.0 0.0 0.0"/>
        <parent link="Link1"/>
        <child link="Link2"/>
        <axis xyz="1.0 0.0 0.0"/>
        <limit lower="-1.919863" upper="-0.174533" effort="0" velocity="0"/>
    </joint>

    <link name="Link2_Virtual">
        <visual>
            <origin xyz="0.0 0.0 0.0" rpy="0.0 1.57 0.0"/>
            <geometry>
                <cylinder radius="0.001" length="0.0001"/>
            </geometry>
            <material name="">
                <color rgba="1.0 0.0 0.0 0.0"/>
            </material>
        </visual>
        <collision>
            <origin xyz="0.0 0.0 0.0" rpy="0.0 0.0 0.0"/>
            <geometry>
                <cylinder radius="0.0001" length="0.0001"/>
            </geometry>
        </collision>
    </link>

    <joint name="Joint2_mimic" type="revolute">
        <origin xyz="0.01 -0.18 -0.0002" rpy="0.0 0.0 0.0"/>
        <parent link="Link2"/>
        <child link="Link2_Virtual"/>
        <axis xyz="1.0 0.0 0.0"/>
        <limit lower="-3.14" upper="3.14" effort="30" velocity="1"/>
        <mimic joint="Joint2" multiplier="-1" offset="0" />
    </joint>

    <link name="Link3">
        <visual>
            <origin xyz="0.0 0.0 0.0" rpy="-1.47 0.0 0.0"/>
            <geometry>
                <mesh filename="package://wsr_desc/meshes/Link3.stl" scale="0.01 0.01 0.01"/>
            </geometry>
            <material name="">
                <color rgba="1.0 0.0 0.0 1.0"/>
            </material>
        </visual>
    </link>

    <joint name="Joint3" type="revolute">
        <origin xyz="0.0 0.0 0.0" rpy="0.0 0.0 0.0"/>
        <parent link="Link2_Virtual"/>
        <child link="Link3"/>
        <axis xyz="1.0 0.0 0.0"/>
        <limit lower="-0.5" upper="1.3" effort="0" velocity="0"/>
    </joint>

    <link name="Link4">
        <visual>
            <origin xyz="0.0 0.0 0.0" rpy="0.08 0.0 0.0"/>
            <geometry>
                <mesh filename="package://wsr_desc/meshes/Link4.stl" scale="0.01 0.01 0.01"/>
            </geometry>
            <material name="">
                <color rgba="0.0 0.275 0.0 1.0"/>
            </material>
        </visual>
    </link>

    <joint name="Joint4" type="revolute">
        <origin xyz="0.0 -0.185 0.055" rpy="0.0 0.0 0.0"/>
        <parent link="Link3"/>
        <child link="Link4"/>
        <axis xyz="1.0 0.0 0.0"/>
        <limit lower="-3.14" upper="3.14" effort="0" velocity="0"/>
        <mimic joint="Joint3" multiplier="-1" offset="0" />
    </joint>

    <link name="gripper">
        <visual>
            <origin xyz="0.0 0.0 0.0" rpy="0.0 0.0 0.0"/>
            <geometry>
                <mesh filename="package://wsr_desc/meshes/suction gripper.stl" scale="0.0005 0.0005 0.0005"/>
            </geometry>
        </visual>
    </link>

    <joint name="joint5" type="fixed">
        <origin xyz="0.022 0.001 -0.04" rpy="0.0 0.0 0.0"/>
       <parent link="Link4"/>
       <child link="gripper"/>
    </joint>

  <transmission name="trans_1">
    <type>transmission_interface/SimpleTransmission</type>
    <joint name="joint_1">
      <hardwareInterface>PositionJointInterface</hardwareInterface>
    </joint>
    <actuator name="servo1">
      <hardwareInterface>PositionJointInterface</hardwareInterface>
      <mechanicalReduction>1</mechanicalReduction>
    </actuator>
  </transmission>

  <transmission name="trans_2">
    <type>transmission_interface/SimpleTransmission</type>
    <joint name="joint_2">
      <hardwareInterface>PositionJointInterface</hardwareInterface>
    </joint>
    <actuator name="servo2">
      <hardwareInterface>PositionJointInterface</hardwareInterface>
      <mechanicalReduction>1</mechanicalReduction>
    </actuator>
  </transmission>

  <transmission name="trans_3">
    <type>transmission_interface/SimpleTransmission</type>
    <joint name="joint_3">
      <hardwareInterface>PositionJointInterface</hardwareInterface>
    </joint>
    <actuator name="servo3">
      <hardwareInterface>PositionJointInterface</hardwareInterface>
      <mechanicalReduction>1</mechanicalReduction>
    </actuator>
  </transmission>

</robot>